Workbook

Sheet Sheet1
A1: Virtus Health | F1: 45949
F2: Calculated weeks APA
A3: Employee ID | B3: Entity List | C3: LSL Instrument | D3: Status | E3: LSL start date | F3: Entitlement (Weeks) | G3: Micropay balance in weeks | H3: Variance | I3: Comment
A4: AU21005 | B4: VIC-TAS | C4: MIVFS2022 | D4: Full time | E4: =VLOOKUP(A4,'[1]Virtus SAMPLE PositionHistorySa'!$A:$L,12,0) | F4: 54.11 | G4: =VLOOKUP(A4,Sheet3!A:K,10,0)/38 | H4: =F4-G4
A5: 60125 | B5: NSW-QLD | C5: QN2025 | D5: Full time | E5: =VLOOKUP(A5,'[1]Virtus SAMPLE PositionHistorySa'!$A:$L,12,0) | F5: 10.81 | G5: =VLOOKUP(A5,Sheet3!A:K,10,0)/38 | H5: =F5-G5
A6: 90145 | B6: NSW-QLD | C6: IVFS2023 | D6: Part time | E6: =VLOOKUP(A6,'[1]Virtus SAMPLE PositionHistorySa'!$A:$L,12,0) | F6: 25.10
A7: 80108 | B7: NSW-QLD | C7: QS2024 | D7: Part time | E7: =VLOOKUP(A7,'[1]Virtus SAMPLE PositionHistorySa'!$A:$L,12,0) | F7: 20.90
A8: 20082 | B8: NSW-QLD | C8: NSW | D8: Full time | E8: =VLOOKUP(A8,'[1]Virtus SAMPLE PositionHistorySa'!$A:$L,12,0) | F8: 15.28 | G8: =VLOOKUP(A8,Sheet3!A:K,10,0)/38 | H8: =F8-G8
A9: 80026 | B9: NSW-QLD | C9: QLD | D9: Part time | E9: =VLOOKUP(A9,'[1]Virtus SAMPLE PositionHistorySa'!$A:$L,12,0) | F9: 2.25
A10: AU21025 | B10: VIC-TAS | C10: MIVFS2022 | D10: Full time | E10: =VLOOKUP(A10,'[1]Virtus SAMPLE PositionHistorySa'!$A:$L,12,0) | F10: 41.69 | G10: =VLOOKUP(A10,Sheet3!A:K,10,0)/38 | H10: =F10-G10
A11: 60118 | B11: NSW-QLD | C11: QN2025 | D11: Part time | E11: =VLOOKUP(A11,'[1]Virtus SAMPLE PositionHistorySa'!$A:$L,12,0) | F11: 25.14
A12: 60018 | B12: NSW-QLD | C12: QN2025 | D12: Part time | E12: =VLOOKUP(A12,'[1]Virtus SAMPLE PositionHistorySa'!$A:$L,12,0) | F12: 23.33
A13: 80042 | B13: NSW-QLD | C13: QS2024 | D13: Full time | E13: =VLOOKUP(A13,'[1]Virtus SAMPLE PositionHistorySa'!$A:$L,12,0) | F13: 20.71 | G13: =VLOOKUP(A13,Sheet3!A:K,10,0)/38 | H13: =F13-G13
A14: 20063 | B14: NSW-QLD | C14: IVFS2023 | D14: Part time | E14: =VLOOKUP(A14,'[1]Virtus SAMPLE PositionHistorySa'!$A:$L,12,0) | F14: 0.00
A15: AU21035 | B15: VIC-TAS | C15: MIVFS2022 | D15: Full time | E15: =VLOOKUP(A15,'[1]Virtus SAMPLE PositionHistorySa'!$A:$L,12,0) | F15: 40.66 | G15: =VLOOKUP(A15,Sheet3!A:K,10,0)/38 | H15: =F15-G15
A16: 20156 | B16: NSW-QLD | C16: IVFN2021 | D16: Full time | E16: =VLOOKUP(A16,'[1]Virtus SAMPLE PositionHistorySa'!$A:$L,12,0) | F16: 20.32 | G16: =VLOOKUP(A16,Sheet3!A:K,10,0)/38 | H16: =F16-G16
A17: 19802 | B17: NSW-QLD | C17: IVFN2021 | D17: Full time | E17: =VLOOKUP(A17,'[1]Virtus SAMPLE PositionHistorySa'!$A:$L,12,0) | F17: 18.67 | G17: =VLOOKUP(A17,Sheet3!A:K,10,0)/38 | H17: =F17-G17
A18: 20146 | B18: NSW-QLD | C18: NSW | D18: Full time | E18: =VLOOKUP(A18,'[1]Virtus SAMPLE PositionHistorySa'!$A:$L,12,0) | F18: 17.64 | G18: =VLOOKUP(A18,Sheet3!A:K,10,0)/38 | H18: =F18-G18
A19: 20172 | B19: NSW-QLD | C19: IVFN2021 | D19: Part time | E19: =VLOOKUP(A19,'[1]Virtus SAMPLE PositionHistorySa'!$A:$L,12,0) | F19: 6.89
A20: 60112 | B20: NSW-QLD | C20: QN2025 | D20: Casual | E20: =VLOOKUP(A20,'[1]Virtus SAMPLE PositionHistorySa'!$A:$L,12,0) | F20: 26.05
A21: 80031 | B21: NSW-QLD | C21: QN2025 | D21: Part time | E21: =VLOOKUP(A21,'[1]Virtus SAMPLE PositionHistorySa'!$A:$L,12,0) | F21: 5.40
A22: 20080 | B22: NSW-QLD | C22: IVFS2023 | D22: Part time | E22: =VLOOKUP(A22,'[1]Virtus SAMPLE PositionHistorySa'!$A:$L,12,0) | F22: 11.80
A23: 20091 | B23: NSW-QLD | C23: IVFS2023 | D23: Part time | E23: =VLOOKUP(A23,'[1]Virtus SAMPLE PositionHistorySa'!$A:$L,12,0) | F23: 8.22
A24: 20056 | B24: NSW-QLD | C24: IVFS2023 | D24: Part time | E24: =VLOOKUP(A24,'[1]Virtus SAMPLE PositionHistorySa'!$A:$L,12,0) | F24: 0.00
A25: 80434 | B25: NSW-QLD | C25: QN2025 | D25: Part time | E25: =VLOOKUP(A25,'[1]Virtus SAMPLE PositionHistorySa'!$A:$L,12,0) | F25: 22.11
A26: 40007 | B26: NSW-QLD | C26: IVFN2021 | D26: Part time | E26: =VLOOKUP(A26,'[1]Virtus SAMPLE PositionHistorySa'!$A:$L,12,0) | F26: 1.62
A27: 20123 | B27: NSW-QLD | C27: IVFS2023 | D27: Part time | E27: =VLOOKUP(A27,'[1]Virtus SAMPLE PositionHistorySa'!$A:$L,12,0) | F27: 12.15
A28: 153 | B28: VIC-TAS | C28: MIVFN2023 | D28: Part time | E28: =VLOOKUP(A28,'[1]Virtus SAMPLE PositionHistorySa'!$A:$L,12,0) | F28: 32.55
A29: 165 | B29: VIC-TAS | C29: MIVFS2022 | D29: Full time | E29: =VLOOKUP(A29,'[1]Virtus SAMPLE PositionHistorySa'!$A:$L,12,0) | F29: 32.11 | G29: =VLOOKUP(A29,Sheet3!A:K,10,0)/38 | H29: =F29-G29
A30: 198 | B30: VIC-TAS | C30: MIVFS2022 | D30: Part time | E30: =VLOOKUP(A30,'[1]Virtus SAMPLE PositionHistorySa'!$A:$L,12,0) | F30: 30.96
A31: 50027 | B31: NSW-QLD | C31: IVFN2021 | D31: Part time | E31: =VLOOKUP(A31,'[1]Virtus SAMPLE PositionHistorySa'!$A:$L,12,0) | F31: 15.69
A32: 214 | B32: VIC-TAS | C32: MIVFS2022 | D32: Full time | E32: =VLOOKUP(A32,'[1]Virtus SAMPLE PositionHistorySa'!$A:$L,12,0) | F32: 30.13 | G32: =VLOOKUP(A32,Sheet3!A:K,10,0)/38 | H32: =F32-G32
A33: 39 | B33: VIC-TAS | C33: TIVF2024 | D33: Part time | E33: =VLOOKUP(A33,'[1]Virtus SAMPLE PositionHistorySa'!$A:$L,12,0) | F33: 15.13
A34: 60129 | B34: NSW-QLD | C34: QN2025 | D34: Part time | E34: =VLOOKUP(A34,'[1]Virtus SAMPLE PositionHistorySa'!$A:$L,12,0) | F34: 0.00
A35: 20175 | B35: NSW-QLD | C35: IVFN2021 | D35: Part time | E35: =VLOOKUP(A35,'[1]Virtus SAMPLE PositionHistorySa'!$A:$L,12,0) | F35: 0.00
A36: 20033 | B36: NSW-QLD | C36: IVFS2023 | D36: Full time | E36: =VLOOKUP(A36,'[1]Virtus SAMPLE PositionHistorySa'!$A:$L,12,0) | F36: 3.05 | G36: =VLOOKUP(A36,Sheet3!A:K,10,0)/38 | H36: =F36-G36
A37: 80105 | B37: NSW-QLD | C37: QS2024 | D37: Full time | E37: =VLOOKUP(A37,'[1]Virtus SAMPLE PositionHistorySa'!$A:$L,12,0) | F37: 5.89 | G37: =VLOOKUP(A37,Sheet3!A:K,10,0)/38 | H37: =F37-G37
A38: 20752 | B38: NSW-QLD | C38: QLD | D38: =VLOOKUP(A38,Sheet3!A:E,5,0) | E38: =VLOOKUP(A38,'[1]Virtus SAMPLE PositionHistorySa'!$A:$L,12,0) | F38: 13.91
A39: 20016 | B39: NSW-QLD | C39: IVFT2024 | D39: Part time | E39: =VLOOKUP(A39,'[1]Virtus SAMPLE PositionHistorySa'!$A:$L,12,0) | F39: 2.26
A40: 318 | B40: VIC-TAS | C40: MIVFS2022 | D40: Part time | E40: =VLOOKUP(A40,'[1]Virtus SAMPLE PositionHistorySa'!$A:$L,12,0) | F40: 27.67
...

Sheet Sheet2
A1: Employee ID | B1: Employee DOB | C1: Cohort | D1: System | E1: Title | F1: Position Effective Date | G1: Position End Date | H1: LSL Instrument | I1: State | J1: Employment Status | K1: Commencement Date | L1: LSL Adjusted Start Date | M1: Termination Date | N1: Termination Reason | O1: Fixed Ordinary Weekly Hours
A2: 12 | C2: VIC-TAS | D2: Virtus Health | E2: Embryologist | F2: 8/22/2011 | H2: TIVF2024 | I2: TAS | J2: Part Time | K2: 8/22/2011 | L2: 8/22/2011 | O2: 22.5
A3: 20 | C3: VIC-TAS | D3: Virtus Health | E3: Registered Nurse | F3: 4/16/2012 | H3: TIVF2024 | I3: TAS | J3: Casual | K3: 4/16/2012 | L3: 4/16/2012 | O3: 38
A4: 23 | C4: VIC-TAS | D4: Virtus Health | E4: Scientific Director | F4: 1/15/2001 | H4: TAS | I4: TAS | J4: Full Time | K4: 1/15/2001 | L4: 1/15/2001 | O4: 37.5
A5: 32 | C5: VIC-TAS | D5: Virtus Health | E5: Embryologist | F5: 40424 | H5: TIVF2024 | I5: TAS | J5: Full Time | K5: 40424 | L5: 40424 | O5: 37.5
A6: 38 | C6: VIC-TAS | D6: Virtus Health | E6: Registered Nurse | F6: 4/17/2012 | H6: TIVF2024 | I6: TAS | J6: Part Time | K6: 4/17/2012 | L6: 4/17/2012 | O6: 15
A7: 39 | C7: VIC-TAS | D7: Virtus Health | E7: Registered Nurse | F7: 39604 | H7: TIVF2024 | I7: TAS | J7: Part Time | K7: 39604 | L7: 39604 | O7: 21.5
A8: 45 | C8: VIC-TAS | D8: Virtus Health | E8: Patient Liaison Administrator | F8: 2/16/2016 | H8: TIVF2024 | I8: TAS | J8: Part Time | K8: 2/16/2016 | L8: 2/16/2016 | O8: 27.5
A9: 56 | C9: VIC-TAS | D9: Virtus Health | E9: Associate Nurse Unit Manager | F9: 3/27/2017 | H9: TIVF2024 | I9: TAS | J9: Part Time | K9: 3/27/2017 | L9: 3/27/2017 | O9: 36
A10: 57 | C10: VIC-TAS | D10: Virtus Health | E10: Enrolled Nurse | F10: 43012 | H10: TIVF2024 | I10: TAS | J10: Part Time | K10: 43012 | L10: 43012 | O10: 24
A11: 76 | C11: VIC-TAS | D11: Virtus Health | E11: Registered Nurse | F11: 7/30/2018 | H11: TIVF2024 | I11: TAS | J11: Part Time | K11: 7/30/2018 | L11: 7/30/2018 | O11: 24
A12: 88 | C12: VIC-TAS | D12: Virtus Health | E12: Embryologist | F12: 43681 | H12: TIVF2024 | I12: TAS | J12: Part Time | K12: 43681 | L12: 43681 | O12: 30
A13: 92 | C13: VIC-TAS | D13: Virtus Health | E13: Patient Administration Services Team Leader | F13: 7/15/2019 | H13: TIVF2024 | I13: TAS | J13: Full Time | K13: 7/15/2019 | L13: 7/15/2019 | O13: 37.5
A14: 95 | C14: VIC-TAS | D14: Virtus Health | E14: Registered Nurse | F14: 9/16/2019 | H14: TIVF2024 | I14: TAS | J14: Part Time | K14: 9/16/2019 | L14: 9/16/2019 | O14: 32
A15: 97 | C15: VIC-TAS | D15: Virtus Health | E15: Registered Nurse | F15: 44106 | H15: TIVF2024 | I15: TAS | J15: Full Time | K15: 44106 | L15: 44106 | O15: 37.5
A16: 99 | C16: VIC-TAS | D16: Virtus Health | E16: Registered Nurse | F16: 44106 | H16: TIVF2024 | I16: TAS | J16: Part Time | K16: 44106 | L16: 44106 | O16: 26
A17: 103 | C17: VIC-TAS | D17: Virtus Health | E17: Donor Coordinator | F17: 3/24/2020 | H17: TIVF2024 | I17: TAS | J17: Part Time | K17: 3/24/2020 | L17: 3/24/2020 | O17: 30
A18: 105 | C18: VIC-TAS | D18: Virtus Health | E18: Enrolled Nurse | F18: 44048 | H18: TIVF2024 | I18: TAS | J18: Casual | K18: 44048 | L18: 44048 | O18: 38
A19: 107 | C19: VIC-TAS | D19: Virtus Health | E19: Registered Nurse | F19: 6/15/2020 | H19: TIVF2024 | I19: TAS | J19: Part Time | K19: 6/15/2020 | L19: 6/15/2020 | O19: 16
A20: 109 | C20: VIC-TAS | D20: Virtus Health | E20: Registered Nurse | F20: 44080 | H20: TIVF2024 | I20: TAS | J20: Casual | K20: 44080 | L20: 44080 | O20: 38
A21: 115 | C21: VIC-TAS | D21: Virtus Health | E21: CSSD Theatre Technician | F21: 7/20/2020 | H21: TIVF2024 | I21: TAS | J21: Casual | K21: 7/20/2020 | L21: 7/20/2020 | O21: 38
A22: 118 | C22: VIC-TAS | D22: Virtus Health | E22: Registered Nurse | F22: 44021 | H22: TIVF2024 | I22: TAS | J22: Part Time | K22: 44021 | L22: 44021 | O22: 8
A23: 119 | C23: VIC-TAS | D23: Virtus Health | E23: Director of Nursing | F23: 9/28/2020 | H23: TAS | I23: TAS | J23: Full Time | K23: 9/28/2020 | L23: 9/28/2020 | O23: 37.5
A24: 120 | C24: VIC-TAS | D24: Virtus Health | E24: Registered Nurse | F24: 43932 | H24: TIVF2024 | I24: TAS | J24: Part Time | K24: 43932 | L24: 43932 | O24: 20
A25: 124 | C25: VIC-TAS | D25: Virtus Health | E25: Embryologist | F25: 1/23/2006 | H25: MIVFS2022 | I25: VIC | J25: Part Time | K25: 1/23/2006 | L25: 1/23/2006 | O25: 32
A26: 125 | C26: VIC-TAS | D26: Virtus Health | E26: Registered Nurse | F26: 44199 | H26: TIVF2024 | I26: TAS | J26: Full Time | K26: 44199 | L26: 44199 | O26: 37.5
A27: 131 | C27: VIC-TAS | D27: Virtus Health | E27: Registered Nurse | F27: 44204 | H27: TIVF2024 | I27: TAS | J27: Part Time | K27: 44204 | L27: 44204 | O27: 28
A28: 136 | C28: VIC-TAS | D28: Virtus Health | E28: Administration Team Leader | F28: 44387 | H28: TIVF2024 | I28: TAS | J28: Full Time | K28: 44387 | L28: 44387 | O28: 37.5
A29: 140 | C29: VIC-TAS | D29: Virtus Health | E29: Embryologist | F29: 44481 | H29: TIVF2024 | I29: TAS | J29: Full Time | K29: 44481 | L29: 44481 | O29: 37.5
A30: 141 | C30: VIC-TAS | D30: Virtus Health | E30: Registered Nurse | F30: 11/29/2021 | H30: TIVF2024 | I30: TAS | J30: Casual | K30: 11/29/2021 | L30: 11/29/2021 | O30: 38
A31: 143 | C31: VIC-TAS | D31: Virtus Health | E31: Embryologist | F31: 44866 | H31: TIVF2024 | I31: TAS | J31: Part Time | K31: 44866 | L31: 44866 | O31: 30
A32: 147 | C32: VIC-TAS | D32: Virtus Health | E32: Patient Liaison Administrator | F32: 3/14/2022 | H32: TIVF2024 | I32: TAS | J32: Full Time | K32: 3/14/2022 | L32: 3/14/2022 | O32: 37.5
A33: 148 | C33: VIC-TAS | D33: Virtus Health | E33: Registered Nurse | F33: 3/28/2022 | H33: TIVF2024 | I33: TAS | J33: Part Time | K33: 3/28/2022 | L33: 3/28/2022 | O33: 16
A34: 153 | C34: VIC-TAS | D34: Virtus Health | E34: Registered Nurse | F34: 39295 | H34: MIVFN2023 | I34: VIC | J34: Part Time | K34: 39295 | L34: 39295 | O34: 34.2
A35: 165 | C35: VIC-TAS | D35: Virtus Health | E35: Embryologist | F35: 39359 | H35: MIVFS2022 | I35: VIC | J35: Full Time | K35: 39359 | L35: 39359 | O35: 38
A36: 198 | C36: VIC-TAS | D36: Virtus Health | E36: Genetics Senior Scientist | F36: 39367 | H36: MIVFS2022 | I36: VIC | J36: Part Time | K36: 39367 | L36: 39367 | O36: 22.8
A37: 214 | C37: VIC-TAS | D37: Virtus Health | E37: Genetics Senior Scientist | F37: 39484 | H37: MIVFS2022 | I37: VIC | J37: Full Time | K37: 39484 | L37: 39484 | O37: 38
A38: 235 | C38: VIC-TAS | D38: Virtus Health | E38: Registered Nurse | F38: 8/27/2008 | H38: MIVFN2023 | I38: VIC | J38: Part Time | K38: 8/27/2008 | L38: 8/27/2008 | O38: 22.8
A39: 270 | C39: VIC-TAS | D39: Virtus Health | E39: Clinical Research Associate | F39: 1/19/2009 | H39: MIVFS2022 | I39: VIC | J39: Full Time | K39: 1/19/2009 | L39: 1/19/2009 | O39: 38
A40: 282 | C40: VIC-TAS | D40: Virtus Health | E40: Nurse Unit Manager | F40: 5/18/2009 | H40: MIVFN2023 | I40: VIC | J40: Full Time | K40: 5/18/2009 | L40: 5/18/2009 | O40: 38
...

Sheet Sheet3
A1: Code | B1: Date Hired | C1: Job Classification | D1: Column2 | E1: Employment Type | F1: Award Type | G1: Physical State | H1: Normal Hours Paid | I1: Payroll Company | J1: Column1 | K1: Long Service Leave Balance | L1: Long Service Leave Post Prorata Hours | M1: Long Service Leave Post Prorata Date (Last Processed Period End Date) | N1: Long Service Leave Post Entitlement Date | O1: Long Service Leave Post Entitlement Hours | P1: Long Service Leave Taken | Q1: Termination Date
A2: 20 | B2: 41015 | C2: Registered Nurse | E2: CA - Casual | F2: TAS IVF Nurses Enterprise Agreement | G2: Tasmania | I2: TAS IVF PTY LTD | M2: 41015 | N2: 41015
A3: 994 | B3: 42928 | C3: Health Information Manager | E3: CA - Casual | F3: Common Law Employment Contract | G3: Victoria | I3: MELBOURNE IVF | M3: 42928 | N3: 42928
A4: 1140 | B4: 43726 | C4: Registered Nurse | E4: CA - Casual | F4: Melbourne IVF Nurses Enterprise Agreement | G4: Victoria | I4: MELBOURNE IVF | M4: 43726 | N4: 43726
A5: 105 | B5: 43959 | C5: Enrolled Nurse | E5: CA - Casual | F5: TAS IVF Nurses Enterprise Agreement | G5: Tasmania | I5: TAS IVF PTY LTD | M5: 43959 | N5: 43959
A6: 109 | B6: 43991 | C6: Registered Nurse | E6: CA - Casual | F6: TAS IVF Nurses Enterprise Agreement | G6: Tasmania | I6: TAS IVF PTY LTD | M6: 43991 | N6: 43991
A7: 1198 | B7: 44008 | C7: Enrolled Nurse | E7: CA - Casual | F7: Melbourne IVF Nurses Enterprise Agreement | G7: Victoria | I7: MELBOURNE IVF | M7: 44008 | N7: 44008
A8: 115 | B8: 44032 | C8: CSSD Theatre Technician | E8: CA - Casual | F8: TAS IVF Support Services Enterprise Agreement | G8: Tasmania | I8: TAS IVF PTY LTD | M8: 44032 | N8: 44032
A9: 1262 | B9: 44292 | C9: Courier | E9: CA - Casual | F9: Health Professionals and Support Services Award | G9: Victoria | I9: MELBOURNE IVF | M9: 44292 | N9: 44292
A10: 1324 | B10: 44522 | C10: Registered Nurse | E10: CA - Casual | F10: Melbourne IVF Nurses Enterprise Agreement | G10: Victoria | I10: MELBOURNE IVF | M10: 44522 | N10: 44522
A11: 1441 | B11: 44525 | C11: Enrolled Nurse | E11: CA - Casual | F11: Melbourne IVF Nurses Enterprise Agreement | G11: Victoria | I11: MELBOURNE IVF | M11: 44525 | N11: 44525
A12: 141 | B12: 44529 | C12: Registered Nurse | E12: CA - Casual | F12: TAS IVF Nurses Enterprise Agreement | G12: Tasmania | I12: TAS IVF PTY LTD | M12: 44529 | N12: 44529
A13: 1459 | B13: 44648 | C13: Registered Nurse | E13: CA - Casual | F13: Melbourne IVF Nurses Enterprise Agreement | G13: Victoria | I13: MELBOURNE IVF | M13: 44648 | N13: 44648
A14: 529 | B14: 41043 | C14: Registered Nurse | E14: CA - Casual | F14: Melbourne IVF Nurses Enterprise Agreement | G14: Victoria | I14: MELBOURNE IVF | K14: -0.2 | L14: 195.00 | M14: 44695 | N14: 41043 | P14: 195.20
A15: AU22629 | B15: 44821 | C15: Enrolled Nurse | E15: CA - Casual | F15: Melbourne IVF Nurses Enterprise Agreement | G15: Victoria | I15: MELBOURNE IVF | M15: 44821 | N15: 44821
A16: AU22641 | B16: 44890 | C16: Registered Nurse | E16: CA - Casual | F16: TAS IVF Nurses Enterprise Agreement | G16: Tasmania | I16: TAS IVF PTY LTD | M16: 44890 | N16: 44890
A17: AU22686 | B17: 44909 | C17: Registered Nurse | E17: CA - Casual | F17: Melbourne IVF Nurses Enterprise Agreement | G17: Victoria | I17: MELBOURNE IVF | M17: 44909 | N17: 44909
A18: AU22704 | B18: 44935 | C18: Administration Clerk | E18: CA - Casual | F18: Melbourne IVF Support Services Enterprise Agreement | G18: Victoria | I18: MELBOURNE IVF | M18: 44935 | N18: 44935
A19: 932 | B19: 42443 | C19: Registered Nurse | E19: CA - Casual | F19: Melbourne IVF Nurses Enterprise Agreement | G19: Victoria | I19: MELBOURNE IVF | L19: 72.72 | M19: 44990 | N19: 42443 | P19: 72.72
A20: AU22772 | B20: 44991 | C20: Clinical Research Scientist | E20: FP - Full Time Waged | F20: Melbourne IVF Medical Scientists Enterprise Agreement | G20: Victoria | H20: 76.00 | I20: MELBOURNE IVF | K20: 1.08 | L20: 1.08 | M20: 44997 | N20: 44991
A21: AU23015 | B21: 45198 | C21: Enrolled Nurse | E21: CA - Casual | F21: Melbourne IVF Nurses Enterprise Agreement | G21: Victoria | I21: MELBOURNE IVF | K21: 10.35 | L21: 10.35 | M21: 45075 | N21: 45075
A22: AU22898 | B22: 45110 | C22: Registered Nurse | E22: CA - Casual | F22: TAS IVF Nurses Enterprise Agreement | G22: Tasmania | I22: TAS IVF PTY LTD | M22: 45110 | N22: 45110
A23: AU22912 | B23: 45119 | C23: Theatre Technician | E23: CA - Casual | F23: Melbourne IVF Support Services Enterprise Agreement | G23: Victoria | I23: MELBOURNE IVF | M23: 45119 | N23: 45119
A24: AU22934 | B24: 45141 | C24: Registered Nurse | E24: CA - Casual | F24: TAS IVF Nurses Enterprise Agreement | G24: Tasmania | I24: TAS IVF PTY LTD | M24: 45141 | N24: 45141
A25: AU22960 | B25: 45148 | C25: Patient Liaison Administrator | E25: CA - Casual | F25: TAS IVF Support Services Enterprise Agreement | G25: Tasmania | I25: TAS IVF PTY LTD | M25: 45148 | N25: 45148
A26: AU22975 | B26: 45181 | C26: Registered Nurse | E26: CA - Casual | F26: TAS IVF Nurses Enterprise Agreement | G26: Tasmania | I26: TAS IVF PTY LTD | M26: 45181 | N26: 45181
A27: AU22981 | B27: 45191 | C27: Registered Nurse | E27: CA - Casual | F27: TAS IVF Nurses Enterprise Agreement | G27: Tasmania | I27: TAS IVF PTY LTD | M27: 45191 | N27: 45191
A28: AU23008 | B28: 45201 | C28: Theatre Orderly | E28: CA - Casual | F28: TAS IVF Support Services Enterprise Agreement | G28: Tasmania | I28: TAS IVF PTY LTD | M28: 45201 | N28: 45201
A29: AU23004 | B29: 45224 | C29: Enrolled Nurse | E29: CA - Casual | F29: TAS IVF Nurses Enterprise Agreement | G29: Tasmania | I29: TAS IVF PTY LTD | M29: 45224 | N29: 45224
A30: AU23078 | B30: 45273 | C30: General Practitioner | E30: CO - Contract | F30: Common Law Employment Contract | G30: Victoria | H30: 38.00 | I30: MELBOURNE IVF | M30: 45273 | N30: 45273
A31: AU23088 | B31: 45341 | C31: Registered Nurse | E31: CA - Casual | F31: TAS IVF Nurses Enterprise Agreement | G31: Tasmania | I31: TAS IVF PTY LTD | M31: 45341 | N31: 45341
A32: AU23289 | B32: 45509 | C32: Registered Nurse | E32: CA - Casual | F32: TAS IVF Nurses Enterprise Agreement | G32: Tasmania | I32: TAS IVF PTY LTD | M32: 45509 | N32: 45509
A33: AU23344 | B33: 45538 | C33: Project Operation | E33: CA - Casual | F33: Common Law Employment Contract | G33: Victoria | I33: MELBOURNE IVF | M33: 45538 | N33: 45538
A34: AU23353 | B34: 45544 | C34: Phlebotomist | E34: CA - Casual | F34: Health Professionals and Support Services Award | G34: Victoria | I34: MELBOURNE IVF | M34: 45544 | N34: 45544
A35: AU23397 | B35: 45574 | C35: Administration Clerk | E35: CA - Casual | F35: Melbourne IVF Support Services Enterprise Agreement | G35: Victoria | I35: MELBOURNE IVF | M35: 45574 | N35: 45574
A36: AU23409 | B36: 45595 | C36: Registered Nurse | E36: CA - Casual | F36: TAS IVF Nurses Enterprise Agreement | G36: Tasmania | I36: TAS IVF PTY LTD | M36: 45595 | N36: 45595
A37: AU23416 | B37: 45601 | C37: Administration Clerk | E37: CA - Casual | F37: Melbourne IVF Support Services Enterprise Agreement | G37: Victoria | I37: MELBOURNE IVF | M37: 45601 | N37: 45601
A38: AU23463 | B38: 45630 | C38: Theatre Technician | E38: CA - Casual | F38: Melbourne IVF Support Services Enterprise Agreement | G38: Victoria | I38: MELBOURNE IVF | M38: 45630 | N38: 45630
A39: AU23461 | B39: 45635 | C39: Assistant in Nursing | E39: CA - Casual | F39: Common Law Employment Contract | G39: Victoria | I39: MELBOURNE IVF | M39: 45635 | N39: 45635
A40: AU23462 | B40: 45642 | C40: Registered Nurse | E40: CA - Casual | F40: Melbourne IVF Nurses Enterprise Agreement | G40: Victoria | I40: MELBOURNE IVF | M40: 45642 | N40: 45642
...
